Workbook

Sheet 要約
A1: Beautiful Life 売上予測 要約
A2: すべて「前提」シートの仮置きに基づく試算です。実績が出たら青字・黄色のセルを差し替えてください。
A4: 指標 | B4: 悲観 | C4: 標準 | D4: 楽観 | E4: メモ
A5: 3月の撮影組数(月) | B5: =月次予測!F16 -> 15.12 | C5: =月次予測!F41 -> 19.8414 | D5: =月次予測!F66 -> 25.1328 | E5: 3月=開業から4か月目(継続判断の時点)
A6: 3月の売上(円) | B6: =月次予測!F21 -> 136124 | C6: =月次予測!F46 -> 181520.7 | D6: =月次予測!F71 -> 233238.4
A7: 3月の営業利益(返済前・円) | B7: =月次予測!F25 -> -27576 | C7: =月次予測!F50 -> 14895.7 | D7: =月次予測!F75 -> 63238.4 | E7: 0以上ならトントン以上
A8: 3月末の現金残高(円) | B8: =月次予測!F28 -> 2028311.3 | C8: =月次予測!F53 -> 2150432.8 | D8: =月次予測!F78 -> 2289233.7 | E8: 開業時の手元資金から累計
A9: 損益分岐の撮影組数(月・安定期) | B9: =(前提!B21+前提!B22+前提!B23/12-前提!B15*前提!B16*前提!B17-前提!B19*前提!B20)/前提!B10 -> 29.653846 | C9: =(前提!C21+前提!C22+前提!C23/12-前提!C15*前提!C16*前提!C17-前提!C19*前提!C20)/前提!C10 -> 26.204545 | D9: =(前提!D21+前提!D22+前提!D23/12-前提!D15*前提!D16*前提!D17-前提!D19*前提!D20)/前提!D10 -> 21.311475 | E9: 返済前。会員費・リピートの単価ダウンは含まない
A10: 12か月の営業利益 合計(返済前・円) | B10: =SUM(月次予測!C25:N25) -> -479328.4 | C10: =SUM(月次予測!C50:N50) -> -1125.3 | D10: =SUM(月次予測!C75:N75) -> 546125.2
A11: 12か月の最低現金残高(円) | B11: =MIN(月次予測!C28:N28) -> 1381766.6 | C11: =MIN(月次予測!C53:N53) -> 1859969.7 | D11: =MIN(月次予測!C78:N78) -> 2279237.3 | E11: マイナスなら資金ショート
A12: 開業時の手元資金(円) | B12: =前提!B31 -> 2500000 | C12: =前提!C31 -> 2500000 | D12: =前提!D31 -> 2500000
A13: 3月の判定 | B13: =IF(B7>=0,"トントン以上","赤字") -> 赤字 | C13: =IF(C7>=0,"トントン以上","赤字") -> トントン以上 | D13: =IF(D7>=0,"トントン以上","赤字") -> トントン以上
A15: 注意
A16: ・人件費、代表報酬、税金、設備の減価償却、決算費用の実際の支払い時期は含みません。
A17: ・融資の金利と返済期間は仮置きです。公庫の見積もりで差し替えてください。
A18: ・リピート、雑貨、会員費は実績がありません。融資資料では新規のみの数字を基準にし、これらは上積みとして示すのが安全です。
A19: ・チロペロのデータ(来場組数、新規の割合、1日4〜5組の撮影)はユーザー提供の実績です。

Sheet 前提
A1: Beautiful Life 売上予測 前提条件
A2: 青字=入力(変更可)/ 黄色=要確認の仮置き / 黒字=計算。数字を変えると「月次予測」「要約」が自動で変わります。
A4: 項目 | B4: 悲観 | C4: 標準 | D4: 楽観 | E4: 根拠・メモ
A5: 土日の来場組数(1日あたり) | B5: 40 | C5: 50 | D5: 60 | E5: ユーザー提供: チロペロの土日は平日(20〜30組)の倍近く
A6: 土日の営業日数(月) | B6: 8 | C6: 8.5 | D6: 9 | E6: 月の土日の日数(祝日除く)
A7: 来場者のうち新規の割合 | B7: 0.2 | C7: 0.25 | D7: 0.3 | E7: ユーザー提供: 土日の新規は2〜3割
A8: 新規のうち店舗で撮影する割合 | B8: 0.08 | C8: 0.12 | D8: 0.18 | E8: 出店の実績(新規の約25〜55%が撮影)を1/3に割り引いた仮置き。要検証
A9: その他経路の撮影(月の組数) | B9: 0 | C9: 2 | D9: 4 | E9: 提携サロン・SNS等。未検証の仮置き
A10: 撮影の客単価(円) | B10: 5200 | C10: 5500 | D10: 6100 | E10: セルフ撮影¥4,000／プロカメラマン撮影¥10,000〜 の週末来店ブレンド単価。比率は仮置き(悲観:セルフ80%/プロ20%、標準75/25、楽観65/35)。要確認
A11: リピートの月次再来率(累計顧客に対して) | B11: 0 | C11: 0.05 | D11: 0.1 | E11: ドッグランでは2度目の依頼なし。ブース変更・会員制度での仮置き
A12: リピート時の客単価(新規比) | B12: 0.8 | C12: 0.85 | D12: 0.9 | E12: 会員特典(時間・犬代無料の検討)による単価ダウンの仮置き
A13: 会員化率(累計顧客のうち) | B13: 0 | C13: 0.05 | D13: 0.1 | E13: 会員制度は未設計。仮置き
A14: 会員費(月額・円) | B14: 500 | C14: 500 | D14: 500 | E14: 未決定。仮置き
A15: 雑貨目当ての来店(月の組数) | B15: 1 | C15: 3 | D15: 5 | E15: ユーザー: 数組を想定
A16: 雑貨の客単価(円) | B16: 2000 | C16: 2500 | D16: 3000 | E16: 仮置き
... A29: 返済期間(年) | B29: 5 | C29: 5 | D29: 5 | E29: 仮置き。据置なしで計算
A30: 月返済額(円) | B30: =PMT(B28/12,B29*12,-B25) -> 53242.085 | C30: =PMT(C28/12,C29*12,-C25) -> 53242.085 | D30: =PMT(D28/12,D29*12,-D25) -> 53242.085 | E30: 元利均等の概算
A31: 開業時の手元資金(円) | B31: =B24+B25-B26-B27 -> 2500000 | C31: =C24+C25-C26-C27 -> 2500000 | D31: =D24+D25-D26-D27 -> 2500000 | E31: 資本金+融資−修繕−ブース・備品
A33: 平日の来場組数(1日あたり・組) | B33: 0.5 | C33: 0.65 | D33: 0.8 | E33: ユーザー提供: 平日1日平均0.5組。標準/楽観は同パターンで按分した仮置き
A34: 平日の営業日数(月) | B34: 20 | C34: 20 | D34: 20 | E34: ユーザー提供: 平日20日想定(祝日等除く概算)
A35: 平日撮影の客単価(円・プロカメラマン想定) | B35: 10000 | C35: 10000 | D35: 10000 | E35: 平日は事前予約前提のためプロカメラマン撮影(¥10,000〜)のみと仮定

Sheet 月次予測
A1: 月次予測(3シナリオ)
A2: 12月プレオープン〜翌11月。立ち上がり係数(青字)は月ごとに変更できます。税金・人件費・代表報酬は含みません。
A3: 項目 | B3: 単位 | C3: 12月 | D3: 1月 | E3: 2月 | F3: 3月 | G3: 4月 | H3: 5月 | I3: 6月 | J3: 7月 | K3: 8月 | L3: 9月 | M3: 10月 | N3: 11月
A4: 立ち上がり係数(共通) | C4: 0.3 | D4: 0.7 | E4: 0.9 | F4: 1 | G4: 1 | H4: 1 | I4: 1 | J4: 1 | K4: 1 | L4: 1 | M4: 1 | N4: 1
A6: 【悲観シナリオ】
A7: 立ち上がり係数 | B7: % | C7: =C$4 -> 0.3 | D7: =D$4 -> 0.7 | E7: =E$4 -> 0.9 | F7: =F$4 -> 1 | G7: =G$4 -> 1 | H7: =H$4 -> 1 | I7: =I$4 -> 1 | J7: =J$4 -> 1 | ... N7: =N$4 -> 1
A8: 土日の新規来場 | B8: 組 | C8: =前提!$B$5*前提!$B$6*前提!$B$7 -> 64 | D8: =前提!$B$5*前提!$B$6*前提!$B$7 -> 64 | E8: =前提!$B$5*前提!$B$6*前提!$B$7 -> 64 | F8: =前提!$B$5*前提!$B$6*前提!$B$7 -> 64 | G8: =前提!$B$5*前提!$B$6*前提!$B$7 -> 64 | H8: =前提!$B$5*前提!$B$6*前提!$B$7 -> 64 | I8: =前提!$B$5*前提!$B$6*前提!$B$7 -> 64 | J8: =前提!$B$5*前提!$B$6*前提!$B$7 -> 64 | ... N8: =前提!$B$5*前提!$B$6*前提!$B$7 -> 64
A9: 新規の撮影(店舗) | B9: 組 | C9: =C8*前提!$B$8*C7 -> 1.536 | D9: =D8*前提!$B$8*D7 -> 3.584 | E9: =E8*前提!$B$8*E7 -> 4.608 | F9: =F8*前提!$B$8*F7 -> 5.12 | G9: =G8*前提!$B$8*G7 -> 5.12 | H9: =H8*前提!$B$8*H7 -> 5.12 | I9: =I8*前提!$B$8*I7 -> 5.12 | J9: =J8*前提!$B$8*J7 -> 5.12 | ... N9: =N8*前提!$B$8*N7 -> 5.12
A10: その他経路の撮影 | B10: 組 | C10: =前提!$B$9*C7 -> 0 | D10: =前提!$B$9*D7 -> 0 | E10: =前提!$B$9*E7 -> 0 | F10: =前提!$B$9*F7 -> 0 | G10: =前提!$B$9*G7 -> 0 | H10: =前提!$B$9*H7 -> 0 | I10: =前提!$B$9*I7 -> 0 | J10: =前提!$B$9*J7 -> 0 | ... N10: =前提!$B$9*N7 -> 0
A11: 雑貨目当ての来店 | B11: 組 | C11: =前提!$B$15*C7 -> 0.3 | D11: =前提!$B$15*D7 -> 0.7 | E11: =前提!$B$15*E7 -> 0.9 | F11: =前提!$B$15*F7 -> 1 | G11: =前提!$B$15*G7 -> 1 | H11: =前提!$B$15*H7 -> 1 | I11: =前提!$B$15*I7 -> 1 | J11: =前提!$B$15*J7 -> 1 | ... N11: =前提!$B$15*N7 -> 1
A12: 雑貨来店からの撮影 | B12: 組 | C12: =C11*前提!$B$18 -> 0 | D12: =D11*前提!$B$18 -> 0 | E12: =E11*前提!$B$18 -> 0 | F12: =F11*前提!$B$18 -> 0 | G12: =G11*前提!$B$18 -> 0 | H12: =H11*前提!$B$18 -> 0 | I12: =I11*前提!$B$18 -> 0 | J12: =J11*前提!$B$18 -> 0 | ... N12: =N11*前提!$B$18 -> 0
A13: 新規撮影の合計 | B13: 組 | C13: =C9+C10+C12+前提!$B$33*前提!$B$34*C7 -> 4.536 | D13: =D9+D10+D12+前提!$B$33*前提!$B$34*D7 -> 10.584 | E13: =E9+E10+E12+前提!$B$33*前提!$B$34*E7 -> 13.608 | F13: =F9+F10+F12+前提!$B$33*前提!$B$34*F7 -> 15.12 | G13: =G9+G10+G12+前提!$B$33*前提!$B$34*G7 -> 15.12 | H13: =H9+H10+H12+前提!$B$33*前提!$B$34*H7 -> 15.12 | I13: =I9+I10+I12+前提!$B$33*前提!$B$34*I7 -> 15.12 | J13: =J9+J10+J12+前提!$B$33*前提!$B$34*J7 -> 15.12 | ... N13: =N9+N10+N12+前提!$B$33*前提!$B$34*N7 -> 15.12
A14: 累計顧客(前月末) | B14: 組 | C14: =0 -> 0 | D14: =C14+C13 -> 4.536 | E14: =D14+D13 -> 15.12 | F14: =E14+E13 -> 28.728 | G14: =F14+F13 -> 43.848 | H14: =G14+G13 -> 58.968 | I14: =H14+H13 -> 74.088 | J14: =I14+I13 -> 89.208 | K14: =J14+J13 -> 104.328 | ... N14: =M14+M13 -> 149.688
A15: リピート撮影 | B15: 組 | C15: =C14*前提!$B$11 -> 0 | D15: =D14*前提!$B$11 -> 0 | E15: =E14*前提!$B$11 -> 0 | F15: =F14*前提!$B$11 -> 0 | G15: =G14*前提!$B$11 -> 0 | H15: =H14*前提!$B$11 -> 0 | I15: =I14*前提!$B$11 -> 0 | J15: =J14*前提!$B$11 -> 0 | ... N15: =N14*前提!$B$11 -> 0
A16: 撮影組数 合計 | B16: 組 | C16: =C13+C15 -> 4.536 | D16: =D13+D15 -> 10.584 | E16: =E13+E15 -> 13.608 | F16: =F13+F15 -> 15.12 | G16: =G13+G15 -> 15.12 | H16: =H13+H15 -> 15.12 | I16: =I13+I15 -> 15.12 | J16: =J13+J15 -> 15.12 | ... N16: =N13+N15 -> 15.12
A17: 撮影売上 | B17: 円 | C17: =(C9+C10+C12)*前提!$B$10+前提!$B$33*前提!$B$34*C7*前提!$B$35+C15*前提!$B$10*前提!$B$12 -> 37987.2 | D17: =(D9+D10+D12)*前提!$B$10+前提!$B$33*前提!$B$34*D7*前提!$B$35+D15*前提!$B$10*前提!$B$12 -> 88636.8 | E17: =(E9+E10+E12)*前提!$B$10+前提!$B$33*前提!$B$34*E7*前提!$B$35+E15*前提!$B$10*前提!$B$12 -> 113961.6 | F17: =(F9+F10+F12)*前提!$B$10+前提!$B$33*前提!$B$34*F7*前提!$B$35+F15*前提!$B$10*前提!$B$12 -> 126624 | G17: =(G9+G10+G12)*前提!$B$10+前提!$B$33*前提!$B$34*G7*前提!$B$35+G15*前提!$B$10*前提!$B$12 -> 126624 | H17: =(H9+H10+H12)*前提!$B$10+前提!$B$33*前提!$B$34*H7*前提!$B$35+H15*前提!$B$10*前提!$B$12 -> 126624 | I17: =(I9+I10+I12)*前提!$B$10+前提!$B$33*前提!$B$34*I7*前提!$B$35+I15*前提!$B$10*前提!$B$12 -> 126624 | J17: =(J9+J10+J12)*前提!$B$10+前提!$B$33*前提!$B$34*J7*前提!$B$35+J15*前提!$B$10*前提!$B$12 -> 126624 | ... N17: =(N9+N10+N12)*前提!$B$10+前提!$B$33*前提!$B$34*N7*前提!$B$35+N15*前提!$B$10*前提!$B$12 -> 126624
A18: 会員費 | B18: 円 | C18: =C14*前提!$B$13*前提!$B$14 -> 0 | D18: =D14*前提!$B$13*前提!$B$14 -> 0 | E18: =E14*前提!$B$13*前提!$B$14 -> 0 | F18: =F14*前提!$B$13*前提!$B$14 -> 0 | G18: =G14*前提!$B$13*前提!$B$14 -> 0 | H18: =H14*前提!$B$13*前提!$B$14 -> 0 | I18: =I14*前提!$B$13*前提!$B$14 -> 0 | J18: =J14*前提!$B$13*前提!$B$14 -> 0 | ... N18: =N14*前提!$B$13*前提!$B$14 -> 0
A19: 雑貨売上 | B19: 円 | C19: =C11*前提!$B$16 -> 600 | D19: =D11*前提!$B$16 -> 1400 | E19: =E11*前提!$B$16 -> 1800 | F19: =F11*前提!$B$16 -> 2000 | G19: =G11*前提!$B$16 -> 2000 | H19: =H11*前提!$B$16 -> 2000 | I19: =I11*前提!$B$16 -> 2000 | J19: =J11*前提!$B$16 -> 2000 | ... N19: =N11*前提!$B$16 -> 2000
A20: レンタルケース | B20: 円 | C20: =前提!$B$19*前提!$B$20*C7 -> 2250 | D20: =前提!$B$19*前提!$B$20*D7 -> 5250 | E20: =前提!$B$19*前提!$B$20*E7 -> 6750 | F20: =前提!$B$19*前提!$B$20*F7 -> 7500 | G20: =前提!$B$19*前提!$B$20*G7 -> 7500 | H20: =前提!$B$19*前提!$B$20*H7 -> 7500 | I20: =前提!$B$19*前提!$B$20*I7 -> 7500 | J20: =前提!$B$19*前提!$B$20*J7 -> 7500 | ... N20: =前提!$B$19*前提!$B$20*N7 -> 7500
A21: 売上合計 | B21: 円 | C21: =C17+C18+C19+C20 -> 40837.2 | D21: =D17+D18+D19+D20 -> 95286.8 | E21: =E17+E18+E19+E20 -> 122511.6 | F21: =F17+F18+F19+F20 -> 136124 | G21: =G17+G18+G19+G20 -> 136124 | H21: =H17+H18+H19+H20 -> 136124 | I21: =I17+I18+I19+I20 -> 136124 | J21: =J17+J18+J19+J20 -> 136124 | ... N21: =N17+N18+N19+N20 -> 136124
A22: 雑貨の仕入原価 | B22: 円 | C22: =C19*(1-前提!$B$17) -> 360 | D22: =D19*(1-前提!$B$17) -> 840 | E22: =E19*(1-前提!$B$17) -> 1080 | F22: =F19*(1-前提!$B$17) -> 1200 | G22: =G19*(1-前提!$B$17) -> 1200 | H22: =H19*(1-前提!$B$17) -> 1200 | I22: =I19*(1-前提!$B$17) -> 1200 | J22: =J19*(1-前提!$B$17) -> 1200 | ... N22: =N19*(1-前提!$B$17) -> 1200
A23: 家賃・その他経費 | B23: 円 | C23: =前提!$B$21+前提!$B$22 -> 150000 | D23: =前提!$B$21+前提!$B$22 -> 150000 | E23: =前提!$B$21+前提!$B$22 -> 150000 | F23: =前提!$B$21+前提!$B$22 -> 150000 | G23: =前提!$B$21+前提!$B$22 -> 150000 | H23: =前提!$B$21+前提!$B$22 -> 150000 | I23: =前提!$B$21+前提!$B$22 -> 150000 | J23: =前提!$B$21+前提!$B$22 -> 150000 | ... N23: =前提!$B$21+前提!$B$22 -> 150000
A24: 決算費用(月割) | B24: 円 | C24: =前提!$B$23/12 -> 12500 | D24: =前提!$B$23/12 -> 12500 | E24: =前提!$B$23/12 -> 12500 | F24: =前提!$B$23/12 -> 12500 | G24: =前提!$B$23/12 -> 12500 | H24: =前提!$B$23/12 -> 12500 | I24: =前提!$B$23/12 -> 12500 | J24: =前提!$B$23/12 -> 12500 | ... N24: =前提!$B$23/12 -> 12500
A25: 営業利益(返済前) | B25: 円 | C25: =C21-C22-C23-C24 -> -122022.8 | D25: =D21-D22-D23-D24 -> -68053.2 | E25: =E21-E22-E23-E24 -> -41068.4 | F25: =F21-F22-F23-F24 -> -27576 | G25: =G21-G22-G23-G24 -> -27576 | H25: =H21-H22-H23-H24 -> -27576 | I25: =I21-I22-I23-I24 -> -27576 | J25: =J21-J22-J23-J24 -> -27576 | ... N25: =N21-N22-N23-N24 -> -27576
A26: 融資返済 | B26: 円 | C26: =前提!$B$30 -> 53242.085 | D26: =前提!$B$30 -> 53242.085 | E26: =前提!$B$30 -> 53242.085 | F26: =前提!$B$30 -> 53242.085 | G26: =前提!$B$30 -> 53242.085 | H26: =前提!$B$30 -> 53242.085 | I26: =前提!$B$30 -> 53242.085 | J26: =前提!$B$30 -> 53242.085 | ... N26: =前提!$B$30 -> 53242.085
A27: 月間の資金増減 | B27: 円 | C27: =C25-C26 -> -175264.88 | D27: =D25-D26 -> -121295.28 | E27: =E25-E26 -> -94310.485 | F27: =F25-F26 -> -80818.085 | G27: =G25-G26 -> -80818.085 | H27: =H25-H26 -> -80818.085 | I27: =I25-I26 -> -80818.085 | J27: =J25-J26 -> -80818.085 | ... N27: =N25-N26 -> -80818.085
A28: 月末の現金残高 | B28: 円 | C28: =前提!$B$31+C27 -> 2324735.1 | D28: =C28+D27 -> 2203439.8 | E28: =D28+E27 -> 2109129.3 | F28: =E28+F27 -> 2028311.3 | G28: =F28+G27 -> 1947493.2 | H28: =G28+H27 -> 1866675.1 | I28: =H28+I27 -> 1785857 | J28: =I28+J27 -> 1705038.9 | K28: =J28+K27 -> 1624220.8 | ... N28: =M28+N27 -> 1381766.6
A31: 【標準シナリオ】
A32: 立ち上がり係数 | B32: % | C32: =C$4 -> 0.3 | D32: =D$4 -> 0.7 | E32: =E$4 -> 0.9 | F32: =F$4 -> 1 | G32: =G$4 -> 1 | H32: =H$4 -> 1 | I32: =I$4 -> 1 | J32: =J$4 -> 1 | ... N32: =N$4 -> 1
A33: 土日の新規来場 | B33: 組 | C33: =前提!$C$5*前提!$C$6*前提!$C$7 -> 106.25 | D33: =前提!$C$5*前提!$C$6*前提!$C$7 -> 106.25 | E33: =前提!$C$5*前提!$C$6*前提!$C$7 -> 106.25 | F33: =前提!$C$5*前提!$C$6*前提!$C$7 -> 106.25 | G33: =前提!$C$5*前提!$C$6*前提!$C$7 -> 106.25 | H33: =前提!$C$5*前提!$C$6*前提!$C$7 -> 106.25 | I33: =前提!$C$5*前提!$C$6*前提!$C$7 -> 106.25 | J33: =前提!$C$5*前提!$C$6*前提!$C$7 -> 106.25 | ... N33: =前提!$C$5*前提!$C$6*前提!$C$7 -> 106.25
A34: 新規の撮影(店舗) | B34: 組 | C34: =C33*前提!$C$8*C32 -> 3.825 | D34: =D33*前提!$C$8*D32 -> 8.925 | E34: =E33*前提!$C$8*E32 -> 11.475 | F34: =F33*前提!$C$8*F32 -> 12.75 | G34: =G33*前提!$C$8*G32 -> 12.75 | H34: =H33*前提!$C$8*H32 -> 12.75 | I34: =I33*前提!$C$8*I32 -> 12.75 | J34: =J33*前提!$C$8*J32 -> 12.75 | ... N34: =N33*前提!$C$8*N32 -> 12.75
A35: その他経路の撮影 | B35: 組 | C35: =前提!$C$9*C32 -> 0.6 | D35: =前提!$C$9*D32 -> 1.4 | E35: =前提!$C$9*E32 -> 1.8 | F35: =前提!$C$9*F32 -> 2 | G35: =前提!$C$9*G32 -> 2 | H35: =前提!$C$9*H32 -> 2 | I35: =前提!$C$9*I32 -> 2 | J35: =前提!$C$9*J32 -> 2 | ... N35: =前提!$C$9*N32 -> 2
A36: 雑貨目当ての来店 | B36: 組 | C36: =前提!$C$15*C32 -> 0.9 | D36: =前提!$C$15*D32 -> 2.1 | E36: =前提!$C$15*E32 -> 2.7 | F36: =前提!$C$15*F32 -> 3 | G36: =前提!$C$15*G32 -> 3 | H36: =前提!$C$15*H32 -> 3 | I36: =前提!$C$15*I32 -> 3 | J36: =前提!$C$15*J32 -> 3 | ... N36: =前提!$C$15*N32 -> 3
A37: 雑貨来店からの撮影 | B37: 組 | C37: =C36*前提!$C$18 -> 0.09 | D37: =D36*前提!$C$18 -> 0.21 | E37: =E36*前提!$C$18 -> 0.27 | F37: =F36*前提!$C$18 -> 0.3 | G37: =G36*前提!$C$18 -> 0.3 | H37: =H36*前提!$C$18 -> 0.3 | I37: =I36*前提!$C$18 -> 0.3 | J37: =J36*前提!$C$18 -> 0.3 | ... N37: =N36*前提!$C$18 -> 0.3
A38: 新規撮影の合計 | B38: 組 | C38: =C9+C10+C12+前提!$C$33*前提!$C$34*C7 -> 5.436 | D38: =D9+D10+D12+前提!$C$33*前提!$C$34*D7 -> 12.684 | E38: =E9+E10+E12+前提!$C$33*前提!$C$34*E7 -> 16.308 | F38: =F9+F10+F12+前提!$C$33*前提!$C$34*F7 -> 18.12 | G38: =G9+G10+G12+前提!$C$33*前提!$C$34*G7 -> 18.12 | H38: =H9+H10+H12+前提!$C$33*前提!$C$34*H7 -> 18.12 | I38: =I9+I10+I12+前提!$C$33*前提!$C$34*I7 -> 18.12 | J38: =J9+J10+J12+前提!$C$33*前提!$C$34*J7 -> 18.12 | ... N38: =N9+N10+N12+前提!$C$33*前提!$C$34*N7 -> 18.12
A39: 累計顧客(前月末) | B39: 組 | C39: =0 -> 0 | D39: =C39+C38 -> 5.436 | E39: =D39+D38 -> 18.12 | F39: =E39+E38 -> 34.428 | G39: =F39+F38 -> 52.548 | H39: =G39+G38 -> 70.668 | I39: =H39+H38 -> 88.788 | J39: =I39+I38 -> 106.908 | K39: =J39+J38 -> 125.028 | ... N39: =M39+M38 -> 179.388
A40: リピート撮影 | B40: 組 | C40: =C39*前提!$C$11 -> 0 | D40: =D39*前提!$C$11 -> 0.2718 | E40: =E39*前提!$C$11 -> 0.906 | F40: =F39*前提!$C$11 -> 1.7214 | G40: =G39*前提!$C$11 -> 2.6274 | H40: =H39*前提!$C$11 -> 3.5334 | I40: =I39*前提!$C$11 -> 4.4394 | J40: =J39*前提!$C$11 -> 5.3454 | ... N40: =N39*前提!$C$11 -> 8.9694
A41: 撮影組数 合計 | B41: 組 | C41: =C38+C40 -> 5.436 | D41: =D38+D40 -> 12.9558 | E41: =E38+E40 -> 17.214 | F41: =F38+F40 -> 19.8414 | G41: =G38+G40 -> 20.7474 | H41: =H38+H40 -> 21.6534 | I41: =I38+I40 -> 22.5594 | J41: =J38+J40 -> 23.4654 | ... N41: =N38+N40 -> 27.0894
A42: 撮影売上 | B42: 円 | C42: =(C9+C10+C12)*前提!$C$10+前提!$C$33*前提!$C$34*C7*前提!$C$35+C15*前提!$C$10*前提!$C$12 -> 47448 | D42: =(D9+D10+D12)*前提!$C$10+前提!$C$33*前提!$C$34*D7*前提!$C$35+D15*前提!$C$10*前提!$C$12 -> 110712 | E42: =(E9+E10+E12)*前提!$C$10+前提!$C$33*前提!$C$34*E7*前提!$C$35+E15*前提!$C$10*前提!$C$12 -> 142344 | F42: =(F9+F10+F12)*前提!$C$10+前提!$C$33*前提!$C$34*F7*前提!$C$35+F15*前提!$C$10*前提!$C$12 -> 158160 | G42: =(G9+G10+G12)*前提!$C$10+前提!$C$33*前提!$C$34*G7*前提!$C$35+G15*前提!$C$10*前提!$C$12 -> 158160 | H42: =(H9+H10+H12)*前提!$C$10+前提!$C$33*前提!$C$34*H7*前提!$C$35+H15*前提!$C$10*前提!$C$12 -> 158160 | I42: =(I9+I10+I12)*前提!$C$10+前提!$C$33*前提!$C$34*I7*前提!$C$35+I15*前提!$C$10*前提!$C$12 -> 158160 | J42: =(J9+J10+J12)*前提!$C$10+前提!$C$33*前提!$C$34*J7*前提!$C$35+J15*前提!$C$10*前提!$C$12 -> 158160 | ... N42: =(N9+N10+N12)*前提!$C$10+前提!$C$33*前提!$C$34*N7*前提!$C$35+N15*前提!$C$10*前提!$C$12 -> 158160
A43: 会員費 | B43: 円 | C43: =C39*前提!$C$13*前提!$C$14 -> 0 | D43: =D39*前提!$C$13*前提!$C$14 -> 135.9 | E43: =E39*前提!$C$13*前提!$C$14 -> 453 | F43: =F39*前提!$C$13*前提!$C$14 -> 860.7 | G43: =G39*前提!$C$13*前提!$C$14 -> 1313.7 | H43: =H39*前提!$C$13*前提!$C$14 -> 1766.7 | I43: =I39*前提!$C$13*前提!$C$14 -> 2219.7 | J43: =J39*前提!$C$13*前提!$C$14 -> 2672.7 | ... N43: =N39*前提!$C$13*前提!$C$14 -> 4484.7
...
